[2021-08-07 15:10:44,961] {taskinstance.py:896} INFO - Dependencies all met for <TaskInstance: standardized_pipeline.create_standardized_table_orders 2021-08-07T15:05:00+00:00 [queued]>
[2021-08-07 15:10:45,054] {taskinstance.py:896} INFO - Dependencies all met for <TaskInstance: standardized_pipeline.create_standardized_table_orders 2021-08-07T15:05:00+00:00 [queued]>
[2021-08-07 15:10:45,056] {taskinstance.py:1087} INFO - 
--------------------------------------------------------------------------------
[2021-08-07 15:10:45,060] {taskinstance.py:1088} INFO - Starting attempt 1 of 1
[2021-08-07 15:10:45,066] {taskinstance.py:1089} INFO - 
--------------------------------------------------------------------------------
[2021-08-07 15:10:45,101] {taskinstance.py:1107} INFO - Executing <Task(MySqlOperator): create_standardized_table_orders> on 2021-08-07T15:05:00+00:00
[2021-08-07 15:10:45,110] {standard_task_runner.py:52} INFO - Started process 99 to run task
[2021-08-07 15:10:45,130] {standard_task_runner.py:76} INFO - Running: ['***', 'tasks', 'run', 'standardized_pipeline', 'create_standardized_table_orders', '2021-08-07T15:05:00+00:00', '--job-id', '8', '--pool', 'default_pool', '--raw', '--subdir', 'DAGS_FOLDER/standardized_pipeline.py', '--cfg-path', '/tmp/tmpy41g3ak6', '--error-file', '/tmp/tmpw_039uwg']
[2021-08-07 15:10:45,132] {standard_task_runner.py:77} INFO - Job 8: Subtask create_standardized_table_orders
[2021-08-07 15:10:45,250] {logging_mixin.py:104} INFO - Running <TaskInstance: standardized_pipeline.create_standardized_table_orders 2021-08-07T15:05:00+00:00 [running]> on host 840edc4bbc5d
[2021-08-07 15:10:45,392] {taskinstance.py:1302} INFO - Exporting the following env vars:
AIRFLOW_CTX_DAG_OWNER=***
AIRFLOW_CTX_DAG_ID=standardized_pipeline
AIRFLOW_CTX_TASK_ID=create_standardized_table_orders
AIRFLOW_CTX_EXECUTION_DATE=2021-08-07T15:05:00+00:00
AIRFLOW_CTX_DAG_RUN_ID=scheduled__2021-08-07T15:05:00+00:00
[2021-08-07 15:10:45,394] {mysql.py:70} INFO - Executing: CREATE TABLE IF NOT EXISTS standardized.ORDERS (
  `ORDER_KEY` int NOT NULL,
  `CUSTOMER_KEY` int NOT NULL,
  `ORDER_ORDERSTATUS` text NOT NULL,
  `ORDER_TOTALPRICE` int NOT NULL,
  `ORDER_ORDERDATE` date NOT NULL,
  `ORDER_ORDERPRIORITY` text NOT NULL,
  `ORDER_CLERK` text NOT NULL,
  `ORDER_SHIPPRIORITY` int NOT NULL,
  `ORDER_COMMENT` text NOT NULL,
  `INGESTION_TIMESTAMP` datetime DEFAULT CURRENT_TIMESTAMP
) ENGINE=InnoDB DEFAULT CHARSET=utf8mb4 COLLATE=utf8mb4_0900_ai_ci;
[2021-08-07 15:10:45,454] {taskinstance.py:1501} ERROR - Task failed with exception
Traceback (most recent call last):
  File "/home/airflow/.local/lib/python3.6/site-packages/airflow/models/taskinstance.py", line 1157, in _run_raw_task
    self._prepare_and_execute_task_with_callbacks(context, task)
  File "/home/airflow/.local/lib/python3.6/site-packages/airflow/models/taskinstance.py", line 1331, in _prepare_and_execute_task_with_callbacks
    result = self._execute_task(context, task_copy)
  File "/home/airflow/.local/lib/python3.6/site-packages/airflow/models/taskinstance.py", line 1361, in _execute_task
    result = task_copy.execute(context=context)
  File "/home/airflow/.local/lib/python3.6/site-packages/airflow/providers/mysql/operators/mysql.py", line 72, in execute
    hook.run(self.sql, autocommit=self.autocommit, parameters=self.parameters)
  File "/home/airflow/.local/lib/python3.6/site-packages/airflow/hooks/dbapi.py", line 177, in run
    with closing(self.get_conn()) as conn:
  File "/home/airflow/.local/lib/python3.6/site-packages/airflow/providers/mysql/hooks/mysql.py", line 164, in get_conn
    getattr(self, self.conn_name_attr)
  File "/home/airflow/.local/lib/python3.6/site-packages/airflow/hooks/base.py", line 67, in get_connection
    conn = Connection.get_connection_from_secrets(conn_id)
  File "/home/airflow/.local/lib/python3.6/site-packages/airflow/models/connection.py", line 379, in get_connection_from_secrets
    raise AirflowNotFoundException(f"The conn_id `{conn_id}` isn't defined")
airflow.exceptions.AirflowNotFoundException: The conn_id `dwh_id` isn't defined
[2021-08-07 15:10:45,459] {taskinstance.py:1551} INFO - Marking task as FAILED. dag_id=standardized_pipeline, task_id=create_standardized_table_orders, execution_date=20210807T150500, start_date=20210807T151044, end_date=20210807T151045
[2021-08-07 15:10:45,557] {local_task_job.py:149} INFO - Task exited with return code 1
