[2021-08-07 13:00:43,792] {taskinstance.py:896} INFO - Dependencies all met for <TaskInstance: to_datalake_pipeline.extract_from_git 2021-08-07T12:55:00+00:00 [queued]>
[2021-08-07 13:00:43,802] {taskinstance.py:896} INFO - Dependencies all met for <TaskInstance: to_datalake_pipeline.extract_from_git 2021-08-07T12:55:00+00:00 [queued]>
[2021-08-07 13:00:43,803] {taskinstance.py:1087} INFO - 
--------------------------------------------------------------------------------
[2021-08-07 13:00:43,804] {taskinstance.py:1088} INFO - Starting attempt 1 of 1
[2021-08-07 13:00:43,804] {taskinstance.py:1089} INFO - 
--------------------------------------------------------------------------------
[2021-08-07 13:00:43,816] {taskinstance.py:1107} INFO - Executing <Task(PythonOperator): extract_from_git> on 2021-08-07T12:55:00+00:00
[2021-08-07 13:00:43,821] {standard_task_runner.py:52} INFO - Started process 8556 to run task
[2021-08-07 13:00:43,825] {standard_task_runner.py:76} INFO - Running: ['***', 'tasks', 'run', 'to_datalake_pipeline', 'extract_from_git', '2021-08-07T12:55:00+00:00', '--job-id', '20', '--pool', 'default_pool', '--raw', '--subdir', 'DAGS_FOLDER/to_datalake_pipeline.py', '--cfg-path', '/tmp/tmpyuieb7qh', '--error-file', '/tmp/tmpvzjrxhk7']
[2021-08-07 13:00:43,826] {standard_task_runner.py:77} INFO - Job 20: Subtask extract_from_git
[2021-08-07 13:00:43,874] {logging_mixin.py:104} INFO - Running <TaskInstance: to_datalake_pipeline.extract_from_git 2021-08-07T12:55:00+00:00 [running]> on host 4446dd23665f
[2021-08-07 13:00:43,926] {taskinstance.py:1302} INFO - Exporting the following env vars:
AIRFLOW_CTX_DAG_OWNER=***
AIRFLOW_CTX_DAG_ID=to_datalake_pipeline
AIRFLOW_CTX_TASK_ID=extract_from_git
AIRFLOW_CTX_EXECUTION_DATE=2021-08-07T12:55:00+00:00
AIRFLOW_CTX_DAG_RUN_ID=scheduled__2021-08-07T12:55:00+00:00
[2021-08-07 13:00:43,928] {logging_mixin.py:104} INFO - Downloading data from -> https://raw.githubusercontent.com/rezaprimasatya/DTO-DE-JUN-MID/main/data.zip
[2021-08-07 13:00:43,941] {taskinstance.py:1501} ERROR - Task failed with exception
Traceback (most recent call last):
  File "/home/airflow/.local/lib/python3.6/site-packages/urllib3/connection.py", line 160, in _new_conn
    (self._dns_host, self.port), self.timeout, **extra_kw
  File "/home/airflow/.local/lib/python3.6/site-packages/urllib3/util/connection.py", line 61, in create_connection
    for res in socket.getaddrinfo(host, port, family, socket.SOCK_STREAM):
  File "/usr/local/lib/python3.6/socket.py", line 745, in getaddrinfo
    for res in _socket.getaddrinfo(host, port, family, type, proto, flags):
socket.gaierror: [Errno -2] Name or service not known

During handling of the above exception, another exception occurred:

Traceback (most recent call last):
  File "/home/airflow/.local/lib/python3.6/site-packages/urllib3/connectionpool.py", line 677, in urlopen
    chunked=chunked,
  File "/home/airflow/.local/lib/python3.6/site-packages/urllib3/connectionpool.py", line 381, in _make_request
    self._validate_conn(conn)
  File "/home/airflow/.local/lib/python3.6/site-packages/urllib3/connectionpool.py", line 978, in _validate_conn
    conn.connect()
  File "/home/airflow/.local/lib/python3.6/site-packages/urllib3/connection.py", line 309, in connect
    conn = self._new_conn()
  File "/home/airflow/.local/lib/python3.6/site-packages/urllib3/connection.py", line 172, in _new_conn
    self, "Failed to establish a new connection: %s" % e
urllib3.exceptions.NewConnectionError: <urllib3.connection.HTTPSConnection object at 0x7fac42927b70>: Failed to establish a new connection: [Errno -2] Name or service not known

During handling of the above exception, another exception occurred:

Traceback (most recent call last):
  File "/home/airflow/.local/lib/python3.6/site-packages/requests/adapters.py", line 449, in send
    timeout=timeout
  File "/home/airflow/.local/lib/python3.6/site-packages/urllib3/connectionpool.py", line 727, in urlopen
    method, url, error=e, _pool=self, _stacktrace=sys.exc_info()[2]
  File "/home/airflow/.local/lib/python3.6/site-packages/urllib3/util/retry.py", line 446, in increment
    raise MaxRetryError(_pool, url, error or ResponseError(cause))
urllib3.exceptions.MaxRetryError: HTTPSConnectionPool(host='raw.githubusercontent.com', port=443): Max retries exceeded with url: /rezaprimasatya/DTO-DE-JUN-MID/main/data.zip (Caused by NewConnectionError('<urllib3.connection.HTTPSConnection object at 0x7fac42927b70>: Failed to establish a new connection: [Errno -2] Name or service not known',))

During handling of the above exception, another exception occurred:

Traceback (most recent call last):
  File "/home/airflow/.local/lib/python3.6/site-packages/airflow/models/taskinstance.py", line 1157, in _run_raw_task
    self._prepare_and_execute_task_with_callbacks(context, task)
  File "/home/airflow/.local/lib/python3.6/site-packages/airflow/models/taskinstance.py", line 1331, in _prepare_and_execute_task_with_callbacks
    result = self._execute_task(context, task_copy)
  File "/home/airflow/.local/lib/python3.6/site-packages/airflow/models/taskinstance.py", line 1361, in _execute_task
    result = task_copy.execute(context=context)
  File "/home/airflow/.local/lib/python3.6/site-packages/airflow/operators/python.py", line 150, in execute
    return_value = self.execute_callable()
  File "/home/airflow/.local/lib/python3.6/site-packages/airflow/operators/python.py", line 161, in execute_callable
    return self.python_callable(*self.op_args, **self.op_kwargs)
  File "/opt/airflow/dags/extract/extract.py", line 104, in extract_data_from_git
    pipeline.run()
  File "/opt/airflow/dags/extract/extract.py", line 16, in run
    zipped_data = self.download_data("https://raw.githubusercontent.com/rezaprimasatya/DTO-DE-JUN-MID/main/data.zip")
  File "/opt/airflow/dags/extract/extract.py", line 26, in download_data
    r = get(url, stream=True)
  File "/home/airflow/.local/lib/python3.6/site-packages/requests/api.py", line 76, in get
    return request('get', url, params=params, **kwargs)
  File "/home/airflow/.local/lib/python3.6/site-packages/requests/api.py", line 61, in request
    return session.request(method=method, url=url, **kwargs)
  File "/home/airflow/.local/lib/python3.6/site-packages/requests/sessions.py", line 542, in request
    resp = self.send(prep, **send_kwargs)
  File "/home/airflow/.local/lib/python3.6/site-packages/requests/sessions.py", line 655, in send
    r = adapter.send(request, **kwargs)
  File "/home/airflow/.local/lib/python3.6/site-packages/requests/adapters.py", line 516, in send
    raise ConnectionError(e, request=request)
requests.exceptions.ConnectionError: HTTPSConnectionPool(host='raw.githubusercontent.com', port=443): Max retries exceeded with url: /rezaprimasatya/DTO-DE-JUN-MID/main/data.zip (Caused by NewConnectionError('<urllib3.connection.HTTPSConnection object at 0x7fac42927b70>: Failed to establish a new connection: [Errno -2] Name or service not known',))
[2021-08-07 13:00:43,946] {taskinstance.py:1551} INFO - Marking task as FAILED. dag_id=to_datalake_pipeline, task_id=extract_from_git, execution_date=20210807T125500, start_date=20210807T130043, end_date=20210807T130043
[2021-08-07 13:00:43,998] {local_task_job.py:149} INFO - Task exited with return code 1
