[2021-08-08 05:07:03,859] {taskinstance.py:896} INFO - Dependencies all met for <TaskInstance: presentation_pipeline.presentation_dim_parts 2021-08-08T05:00:00+00:00 [queued]>
[2021-08-08 05:07:03,892] {taskinstance.py:896} INFO - Dependencies all met for <TaskInstance: presentation_pipeline.presentation_dim_parts 2021-08-08T05:00:00+00:00 [queued]>
[2021-08-08 05:07:03,894] {taskinstance.py:1087} INFO - 
--------------------------------------------------------------------------------
[2021-08-08 05:07:03,895] {taskinstance.py:1088} INFO - Starting attempt 1 of 1
[2021-08-08 05:07:03,896] {taskinstance.py:1089} INFO - 
--------------------------------------------------------------------------------
[2021-08-08 05:07:03,940] {taskinstance.py:1107} INFO - Executing <Task(MySqlOperator): presentation_dim_parts> on 2021-08-08T05:00:00+00:00
[2021-08-08 05:07:03,951] {standard_task_runner.py:52} INFO - Started process 6916 to run task
[2021-08-08 05:07:03,963] {standard_task_runner.py:76} INFO - Running: ['***', 'tasks', 'run', 'presentation_pipeline', 'presentation_dim_parts', '2021-08-08T05:00:00+00:00', '--job-id', '117', '--pool', 'default_pool', '--raw', '--subdir', 'DAGS_FOLDER/presentation_pipeline.py', '--cfg-path', '/tmp/tmpkrs35a1v', '--error-file', '/tmp/tmp0_0c4nrz']
[2021-08-08 05:07:03,970] {standard_task_runner.py:77} INFO - Job 117: Subtask presentation_dim_parts
[2021-08-08 05:07:04,076] {logging_mixin.py:104} INFO - Running <TaskInstance: presentation_pipeline.presentation_dim_parts 2021-08-08T05:00:00+00:00 [running]> on host 75feb3cfb2a6
[2021-08-08 05:07:04,200] {taskinstance.py:1302} INFO - Exporting the following env vars:
AIRFLOW_CTX_DAG_OWNER=***
AIRFLOW_CTX_DAG_ID=presentation_pipeline
AIRFLOW_CTX_TASK_ID=presentation_dim_parts
AIRFLOW_CTX_EXECUTION_DATE=2021-08-08T05:00:00+00:00
AIRFLOW_CTX_DAG_RUN_ID=scheduled__2021-08-08T05:00:00+00:00
[2021-08-08 05:07:04,202] {mysql.py:70} INFO - Executing: INSERT IGNORE INTO presentation.parts
SELECT 
	DISTINCT 
	p.PART_KEY,
	p.PART_NAME,
	p.PART_SIZE_NUMBER,
	p.PART_CONTAINER_TYPE,
	p.PART_RETAIL_PRICE 
FROM 
	standardized.parts p
WHERE 
	p.INGESTION_TIMESTAMP >= DATE_SUB(NOW(), INTERVAL 5 MINUTE)
[2021-08-08 05:07:04,225] {base.py:78} INFO - Using connection to: id: dwh_id. Host: dwh, Port: 3306, Schema: , Login: root, Password: ***, extra: {}
[2021-08-08 05:07:04,244] {dbapi.py:204} INFO - Running statement: INSERT IGNORE INTO presentation.parts
SELECT 
	DISTINCT 
	p.PART_KEY,
	p.PART_NAME,
	p.PART_SIZE_NUMBER,
	p.PART_CONTAINER_TYPE,
	p.PART_RETAIL_PRICE 
FROM 
	standardized.parts p
WHERE 
	p.INGESTION_TIMESTAMP >= DATE_SUB(NOW(), INTERVAL 5 MINUTE), parameters: None
[2021-08-08 05:07:04,247] {taskinstance.py:1501} ERROR - Task failed with exception
Traceback (most recent call last):
  File "/home/airflow/.local/lib/python3.6/site-packages/airflow/models/taskinstance.py", line 1157, in _run_raw_task
    self._prepare_and_execute_task_with_callbacks(context, task)
  File "/home/airflow/.local/lib/python3.6/site-packages/airflow/models/taskinstance.py", line 1331, in _prepare_and_execute_task_with_callbacks
    result = self._execute_task(context, task_copy)
  File "/home/airflow/.local/lib/python3.6/site-packages/airflow/models/taskinstance.py", line 1361, in _execute_task
    result = task_copy.execute(context=context)
  File "/home/airflow/.local/lib/python3.6/site-packages/airflow/providers/mysql/operators/mysql.py", line 72, in execute
    hook.run(self.sql, autocommit=self.autocommit, parameters=self.parameters)
  File "/home/airflow/.local/lib/python3.6/site-packages/airflow/hooks/dbapi.py", line 184, in run
    self._run_command(cur, sql_statement, parameters)
  File "/home/airflow/.local/lib/python3.6/site-packages/airflow/hooks/dbapi.py", line 208, in _run_command
    cur.execute(sql_statement)
  File "/home/airflow/.local/lib/python3.6/site-packages/MySQLdb/cursors.py", line 206, in execute
    res = self._query(query)
  File "/home/airflow/.local/lib/python3.6/site-packages/MySQLdb/cursors.py", line 319, in _query
    db.query(q)
  File "/home/airflow/.local/lib/python3.6/site-packages/MySQLdb/connections.py", line 259, in query
    _mysql.connection.query(self, query)
MySQLdb._exceptions.OperationalError: (1136, "Column count doesn't match value count at row 1")
[2021-08-08 05:07:04,253] {taskinstance.py:1551} INFO - Marking task as FAILED. dag_id=presentation_pipeline, task_id=presentation_dim_parts, execution_date=20210808T050000, start_date=20210808T050703, end_date=20210808T050704
[2021-08-08 05:07:04,308] {local_task_job.py:149} INFO - Task exited with return code 1
[2021-08-08 05:12:21,121] {taskinstance.py:896} INFO - Dependencies all met for <TaskInstance: presentation_pipeline.presentation_dim_parts 2021-08-08T05:00:00+00:00 [queued]>
[2021-08-08 05:12:21,153] {taskinstance.py:896} INFO - Dependencies all met for <TaskInstance: presentation_pipeline.presentation_dim_parts 2021-08-08T05:00:00+00:00 [queued]>
[2021-08-08 05:12:21,154] {taskinstance.py:1087} INFO - 
--------------------------------------------------------------------------------
[2021-08-08 05:12:21,155] {taskinstance.py:1088} INFO - Starting attempt 1 of 1
[2021-08-08 05:12:21,156] {taskinstance.py:1089} INFO - 
--------------------------------------------------------------------------------
[2021-08-08 05:12:21,174] {taskinstance.py:1107} INFO - Executing <Task(MySqlOperator): presentation_dim_parts> on 2021-08-08T05:00:00+00:00
[2021-08-08 05:12:21,182] {standard_task_runner.py:52} INFO - Started process 461 to run task
[2021-08-08 05:12:21,197] {standard_task_runner.py:76} INFO - Running: ['***', 'tasks', 'run', 'presentation_pipeline', 'presentation_dim_parts', '2021-08-08T05:00:00+00:00', '--job-id', '50', '--pool', 'default_pool', '--raw', '--subdir', 'DAGS_FOLDER/presentation_pipeline.py', '--cfg-path', '/tmp/tmpf05lpb87', '--error-file', '/tmp/tmpd9xgz7vk']
[2021-08-08 05:12:21,199] {standard_task_runner.py:77} INFO - Job 50: Subtask presentation_dim_parts
[2021-08-08 05:12:21,272] {logging_mixin.py:104} INFO - Running <TaskInstance: presentation_pipeline.presentation_dim_parts 2021-08-08T05:00:00+00:00 [running]> on host dbfb9e13da58
[2021-08-08 05:12:21,409] {taskinstance.py:1302} INFO - Exporting the following env vars:
AIRFLOW_CTX_DAG_OWNER=***
AIRFLOW_CTX_DAG_ID=presentation_pipeline
AIRFLOW_CTX_TASK_ID=presentation_dim_parts
AIRFLOW_CTX_EXECUTION_DATE=2021-08-08T05:00:00+00:00
AIRFLOW_CTX_DAG_RUN_ID=scheduled__2021-08-08T05:00:00+00:00
[2021-08-08 05:12:21,412] {mysql.py:70} INFO - Executing: INSERT IGNORE INTO presentation.parts
SELECT 
	DISTINCT 
	p.PART_KEY,
	p.PART_NAME,
	p.PART_SIZE_NUMBER,
	p.PART_CONTAINER_TYPE,
	p.PART_RETAIL_PRICE 
FROM 
	standardized.parts p
WHERE 
	p.INGESTION_TIMESTAMP >= DATE_SUB(NOW(), INTERVAL 5 MINUTE)
[2021-08-08 05:12:21,430] {base.py:78} INFO - Using connection to: id: dwh_id. Host: dwh, Port: 3306, Schema: , Login: root, Password: ***, extra: {}
[2021-08-08 05:12:21,448] {dbapi.py:204} INFO - Running statement: INSERT IGNORE INTO presentation.parts
SELECT 
	DISTINCT 
	p.PART_KEY,
	p.PART_NAME,
	p.PART_SIZE_NUMBER,
	p.PART_CONTAINER_TYPE,
	p.PART_RETAIL_PRICE 
FROM 
	standardized.parts p
WHERE 
	p.INGESTION_TIMESTAMP >= DATE_SUB(NOW(), INTERVAL 5 MINUTE), parameters: None
[2021-08-08 05:12:21,456] {taskinstance.py:1501} ERROR - Task failed with exception
Traceback (most recent call last):
  File "/home/airflow/.local/lib/python3.6/site-packages/airflow/models/taskinstance.py", line 1157, in _run_raw_task
    self._prepare_and_execute_task_with_callbacks(context, task)
  File "/home/airflow/.local/lib/python3.6/site-packages/airflow/models/taskinstance.py", line 1331, in _prepare_and_execute_task_with_callbacks
    result = self._execute_task(context, task_copy)
  File "/home/airflow/.local/lib/python3.6/site-packages/airflow/models/taskinstance.py", line 1361, in _execute_task
    result = task_copy.execute(context=context)
  File "/home/airflow/.local/lib/python3.6/site-packages/airflow/providers/mysql/operators/mysql.py", line 72, in execute
    hook.run(self.sql, autocommit=self.autocommit, parameters=self.parameters)
  File "/home/airflow/.local/lib/python3.6/site-packages/airflow/hooks/dbapi.py", line 184, in run
    self._run_command(cur, sql_statement, parameters)
  File "/home/airflow/.local/lib/python3.6/site-packages/airflow/hooks/dbapi.py", line 208, in _run_command
    cur.execute(sql_statement)
  File "/home/airflow/.local/lib/python3.6/site-packages/MySQLdb/cursors.py", line 206, in execute
    res = self._query(query)
  File "/home/airflow/.local/lib/python3.6/site-packages/MySQLdb/cursors.py", line 319, in _query
    db.query(q)
  File "/home/airflow/.local/lib/python3.6/site-packages/MySQLdb/connections.py", line 259, in query
    _mysql.connection.query(self, query)
MySQLdb._exceptions.OperationalError: (1136, "Column count doesn't match value count at row 1")
[2021-08-08 05:12:21,463] {taskinstance.py:1551} INFO - Marking task as FAILED. dag_id=presentation_pipeline, task_id=presentation_dim_parts, execution_date=20210808T050000, start_date=20210808T051221, end_date=20210808T051221
[2021-08-08 05:12:21,529] {local_task_job.py:149} INFO - Task exited with return code 1
