[2021-08-08 02:02:26,671] {taskinstance.py:896} INFO - Dependencies all met for <TaskInstance: standardized_pipeline.create_standardized_table_orders 2021-08-08T01:55:00+00:00 [queued]>
[2021-08-08 02:02:26,722] {taskinstance.py:896} INFO - Dependencies all met for <TaskInstance: standardized_pipeline.create_standardized_table_orders 2021-08-08T01:55:00+00:00 [queued]>
[2021-08-08 02:02:26,723] {taskinstance.py:1087} INFO - 
--------------------------------------------------------------------------------
[2021-08-08 02:02:26,725] {taskinstance.py:1088} INFO - Starting attempt 1 of 1
[2021-08-08 02:02:26,726] {taskinstance.py:1089} INFO - 
--------------------------------------------------------------------------------
[2021-08-08 02:02:26,741] {taskinstance.py:1107} INFO - Executing <Task(MySqlOperator): create_standardized_table_orders> on 2021-08-08T01:55:00+00:00
[2021-08-08 02:02:26,755] {standard_task_runner.py:52} INFO - Started process 3533 to run task
[2021-08-08 02:02:26,774] {standard_task_runner.py:76} INFO - Running: ['***', 'tasks', 'run', 'standardized_pipeline', 'create_standardized_table_orders', '2021-08-08T01:55:00+00:00', '--job-id', '10', '--pool', 'default_pool', '--raw', '--subdir', 'DAGS_FOLDER/standardized_pipeline.py', '--cfg-path', '/tmp/tmpyb2b2wor', '--error-file', '/tmp/tmp39h9jqef']
[2021-08-08 02:02:26,776] {standard_task_runner.py:77} INFO - Job 10: Subtask create_standardized_table_orders
[2021-08-08 02:02:27,052] {logging_mixin.py:104} INFO - Running <TaskInstance: standardized_pipeline.create_standardized_table_orders 2021-08-08T01:55:00+00:00 [running]> on host 02070657999c
[2021-08-08 02:02:27,334] {taskinstance.py:1302} INFO - Exporting the following env vars:
AIRFLOW_CTX_DAG_OWNER=***
AIRFLOW_CTX_DAG_ID=standardized_pipeline
AIRFLOW_CTX_TASK_ID=create_standardized_table_orders
AIRFLOW_CTX_EXECUTION_DATE=2021-08-08T01:55:00+00:00
AIRFLOW_CTX_DAG_RUN_ID=scheduled__2021-08-08T01:55:00+00:00
[2021-08-08 02:02:27,340] {mysql.py:70} INFO - Executing: CREATE TABLE IF NOT EXISTS orders AS
WITH data_last_5_minutes AS (
	SELECT
        DISTINCT
        CAST(O_ORDERKEY AS SIGNED) AS ORDER_KEY,
        CAST(O_CUSTKEY AS SIGNED) AS CUSTOMER_KEY,
        O_ORDERSTATUS AS ORDER_STATUS_TYPE,
        CAST(O_TOTALPRICE AS SIGNED) AS ORDER_TOTAL_PRICE,
        CAST(O_ORDERDATE AS DATE) AS ORDER_DATE,
        O_ORDERPRIORITY AS ORDER_PRIORITY_TYPE,
        O_CLERK AS ORDER_CLERK,
        O_SHIPPRIORITY AS ORDER_SHIPPRIORITY,
        O_COMMENT AS ORDER_COMMENT
    FROM
        datalake.ORDERS
    WHERE 
        INGESTION_TIMESTAMP >= DATE_SUB(NOW(), INTERVAL 5 MINUTE)
)

SELECT 
	* 
FROM 
	data_last_5_minutes
[2021-08-08 02:02:27,411] {taskinstance.py:1501} ERROR - Task failed with exception
Traceback (most recent call last):
  File "/home/airflow/.local/lib/python3.6/site-packages/airflow/models/taskinstance.py", line 1157, in _run_raw_task
    self._prepare_and_execute_task_with_callbacks(context, task)
  File "/home/airflow/.local/lib/python3.6/site-packages/airflow/models/taskinstance.py", line 1331, in _prepare_and_execute_task_with_callbacks
    result = self._execute_task(context, task_copy)
  File "/home/airflow/.local/lib/python3.6/site-packages/airflow/models/taskinstance.py", line 1361, in _execute_task
    result = task_copy.execute(context=context)
  File "/home/airflow/.local/lib/python3.6/site-packages/airflow/providers/mysql/operators/mysql.py", line 72, in execute
    hook.run(self.sql, autocommit=self.autocommit, parameters=self.parameters)
  File "/home/airflow/.local/lib/python3.6/site-packages/airflow/hooks/dbapi.py", line 177, in run
    with closing(self.get_conn()) as conn:
  File "/home/airflow/.local/lib/python3.6/site-packages/airflow/providers/mysql/hooks/mysql.py", line 164, in get_conn
    getattr(self, self.conn_name_attr)
  File "/home/airflow/.local/lib/python3.6/site-packages/airflow/hooks/base.py", line 67, in get_connection
    conn = Connection.get_connection_from_secrets(conn_id)
  File "/home/airflow/.local/lib/python3.6/site-packages/airflow/models/connection.py", line 379, in get_connection_from_secrets
    raise AirflowNotFoundException(f"The conn_id `{conn_id}` isn't defined")
airflow.exceptions.AirflowNotFoundException: The conn_id `dwh_id` isn't defined
[2021-08-08 02:02:27,428] {taskinstance.py:1551} INFO - Marking task as FAILED. dag_id=standardized_pipeline, task_id=create_standardized_table_orders, execution_date=20210808T015500, start_date=20210808T020226, end_date=20210808T020227
[2021-08-08 02:02:27,571] {local_task_job.py:149} INFO - Task exited with return code 1
