[2021-08-08 02:02:26,937] {taskinstance.py:896} INFO - Dependencies all met for <TaskInstance: standardized_pipeline.create_standardized_table_line_items 2021-08-08T01:55:00+00:00 [queued]>
[2021-08-08 02:02:27,036] {taskinstance.py:896} INFO - Dependencies all met for <TaskInstance: standardized_pipeline.create_standardized_table_line_items 2021-08-08T01:55:00+00:00 [queued]>
[2021-08-08 02:02:27,039] {taskinstance.py:1087} INFO - 
--------------------------------------------------------------------------------
[2021-08-08 02:02:27,040] {taskinstance.py:1088} INFO - Starting attempt 1 of 1
[2021-08-08 02:02:27,042] {taskinstance.py:1089} INFO - 
--------------------------------------------------------------------------------
[2021-08-08 02:02:27,081] {taskinstance.py:1107} INFO - Executing <Task(MySqlOperator): create_standardized_table_line_items> on 2021-08-08T01:55:00+00:00
[2021-08-08 02:02:27,151] {standard_task_runner.py:76} INFO - Running: ['***', 'tasks', 'run', 'standardized_pipeline', 'create_standardized_table_line_items', '2021-08-08T01:55:00+00:00', '--job-id', '13', '--pool', 'default_pool', '--raw', '--subdir', 'DAGS_FOLDER/standardized_pipeline.py', '--cfg-path', '/tmp/tmp14ukhpd9', '--error-file', '/tmp/tmpbizrhr3z']
[2021-08-08 02:02:27,159] {standard_task_runner.py:77} INFO - Job 13: Subtask create_standardized_table_line_items
[2021-08-08 02:02:27,095] {standard_task_runner.py:52} INFO - Started process 3539 to run task
[2021-08-08 02:02:27,399] {logging_mixin.py:104} INFO - Running <TaskInstance: standardized_pipeline.create_standardized_table_line_items 2021-08-08T01:55:00+00:00 [running]> on host 02070657999c
[2021-08-08 02:02:27,666] {taskinstance.py:1302} INFO - Exporting the following env vars:
AIRFLOW_CTX_DAG_OWNER=***
AIRFLOW_CTX_DAG_ID=standardized_pipeline
AIRFLOW_CTX_TASK_ID=create_standardized_table_line_items
AIRFLOW_CTX_EXECUTION_DATE=2021-08-08T01:55:00+00:00
AIRFLOW_CTX_DAG_RUN_ID=scheduled__2021-08-08T01:55:00+00:00
[2021-08-08 02:02:27,670] {mysql.py:70} INFO - Executing: CREATE TABLE IF NOT EXISTS line_items AS
WITH data_last_5_minutes AS (
	SELECT 
        DISTINCT
        CAST(L_ORDERKEY AS SIGNED) AS ORDER_KEY, 
        CAST(L_PARTKEY AS SIGNED) AS PART_KEY, 
        CAST(L_SUPPKEY AS SIGNED) AS SUPPLIER_KEY, 
        CAST(L_LINENUMBER AS SIGNED) AS LINE_TIME_NUMBER, 
        CAST(L_QUANTITY AS SIGNED) AS LINE_ITEM_QUANTITY, 
        CAST(L_EXTENDEDPRICE AS SIGNED) AS LINE_ITEM_EXTENDED_PRICE, 
        CAST(L_DISCOUNT AS SIGNED) AS LINE_ITEM_DISCOUNT, 
        CAST(L_TAX AS SIGNED) AS LINE_ITEM_TAX, 
        L_RETURNFLAG AS LINE_ITEM_RETURN_FLAG, 
        L_LINESTATUS AS LINE_ITEM_STATUS_TYPE, 
        CAST(L_SHIPDATE AS DATE) AS LINE_ITEM_SHIP_DATE, 
        CAST(L_COMMITDATE AS DATE) AS LINE_ITEM_COMMIT_DATE, 
        CAST(L_RECEIPTDATE AS DATE) AS LINE_ITEM_RECEIPT_DATE, 
        L_SHIPINSTRUCT AS LINE_ITEM_SHIP_INSTRUCTION_TYPE, 
        L_SHIPMODE AS LINE_ITEM_SHIP_MODE_TYPE, 
        L_COMMENT AS LINE_ITEM_COMMENT
    FROM 
        datalake.LINEITEM
    WHERE 
        INGESTION_TIMESTAMP >= DATE_SUB(NOW(), INTERVAL 5 MINUTE)
)

SELECT 
	* 
FROM 
	data_last_5_minutes
[2021-08-08 02:02:27,769] {taskinstance.py:1501} ERROR - Task failed with exception
Traceback (most recent call last):
  File "/home/airflow/.local/lib/python3.6/site-packages/airflow/models/taskinstance.py", line 1157, in _run_raw_task
    self._prepare_and_execute_task_with_callbacks(context, task)
  File "/home/airflow/.local/lib/python3.6/site-packages/airflow/models/taskinstance.py", line 1331, in _prepare_and_execute_task_with_callbacks
    result = self._execute_task(context, task_copy)
  File "/home/airflow/.local/lib/python3.6/site-packages/airflow/models/taskinstance.py", line 1361, in _execute_task
    result = task_copy.execute(context=context)
  File "/home/airflow/.local/lib/python3.6/site-packages/airflow/providers/mysql/operators/mysql.py", line 72, in execute
    hook.run(self.sql, autocommit=self.autocommit, parameters=self.parameters)
  File "/home/airflow/.local/lib/python3.6/site-packages/airflow/hooks/dbapi.py", line 177, in run
    with closing(self.get_conn()) as conn:
  File "/home/airflow/.local/lib/python3.6/site-packages/airflow/providers/mysql/hooks/mysql.py", line 164, in get_conn
    getattr(self, self.conn_name_attr)
  File "/home/airflow/.local/lib/python3.6/site-packages/airflow/hooks/base.py", line 67, in get_connection
    conn = Connection.get_connection_from_secrets(conn_id)
  File "/home/airflow/.local/lib/python3.6/site-packages/airflow/models/connection.py", line 379, in get_connection_from_secrets
    raise AirflowNotFoundException(f"The conn_id `{conn_id}` isn't defined")
airflow.exceptions.AirflowNotFoundException: The conn_id `dwh_id` isn't defined
[2021-08-08 02:02:27,778] {taskinstance.py:1551} INFO - Marking task as FAILED. dag_id=standardized_pipeline, task_id=create_standardized_table_line_items, execution_date=20210808T015500, start_date=20210808T020226, end_date=20210808T020227
[2021-08-08 02:02:27,893] {local_task_job.py:149} INFO - Task exited with return code 1
