[2021-08-07 16:36:19,404] {taskinstance.py:896} INFO - Dependencies all met for <TaskInstance: presentation_pipeline.create_presentation_table_date 2021-08-07T16:30:00+00:00 [queued]>
[2021-08-07 16:36:19,458] {taskinstance.py:896} INFO - Dependencies all met for <TaskInstance: presentation_pipeline.create_presentation_table_date 2021-08-07T16:30:00+00:00 [queued]>
[2021-08-07 16:36:19,459] {taskinstance.py:1087} INFO - 
--------------------------------------------------------------------------------
[2021-08-07 16:36:19,460] {taskinstance.py:1088} INFO - Starting attempt 1 of 1
[2021-08-07 16:36:19,461] {taskinstance.py:1089} INFO - 
--------------------------------------------------------------------------------
[2021-08-07 16:36:19,474] {taskinstance.py:1107} INFO - Executing <Task(MySqlOperator): create_presentation_table_date> on 2021-08-07T16:30:00+00:00
[2021-08-07 16:36:19,482] {standard_task_runner.py:52} INFO - Started process 440 to run task
[2021-08-07 16:36:19,494] {standard_task_runner.py:76} INFO - Running: ['***', 'tasks', 'run', 'presentation_pipeline', 'create_presentation_table_date', '2021-08-07T16:30:00+00:00', '--job-id', '40', '--pool', 'default_pool', '--raw', '--subdir', 'DAGS_FOLDER/presentation_pipeline.py', '--cfg-path', '/tmp/tmpg_2m8q__', '--error-file', '/tmp/tmpb46l6y31']
[2021-08-07 16:36:19,498] {standard_task_runner.py:77} INFO - Job 40: Subtask create_presentation_table_date
[2021-08-07 16:36:19,602] {logging_mixin.py:104} INFO - Running <TaskInstance: presentation_pipeline.create_presentation_table_date 2021-08-07T16:30:00+00:00 [running]> on host c8552014663a
[2021-08-07 16:36:19,724] {taskinstance.py:1302} INFO - Exporting the following env vars:
AIRFLOW_CTX_DAG_OWNER=***
AIRFLOW_CTX_DAG_ID=presentation_pipeline
AIRFLOW_CTX_TASK_ID=create_presentation_table_date
AIRFLOW_CTX_EXECUTION_DATE=2021-08-07T16:30:00+00:00
AIRFLOW_CTX_DAG_RUN_ID=scheduled__2021-08-07T16:30:00+00:00
[2021-08-07 16:36:19,725] {mysql.py:70} INFO - Executing: CREATE TABLE IF NOT EXISTS presentation.DATE (
    `DATE_KEY` int NOT NULL AUTO_INCREMENT,
    `DAY` int NOT NULL,
    `WEEK` int NOT NULL,
    `MONTH` int NOT NULL,
    `QUARTER` int NOT NULL,
    `YEAR` int NOT NULL,
    `INGESTION_TIMESTAMP` datetime DEFAULT CURRENT_TIMESTAMP,
    CONSTRAINT `PK_CUSTOMER` PRIMARY KEY (`CUSTOMER_KEY`)
) ENGINE=InnoDB DEFAULT CHARSET=utf8mb4 COLLATE=utf8mb4_0900_ai_ci;
[2021-08-07 16:36:19,739] {base.py:78} INFO - Using connection to: id: dwh_id. Host: dwh, Port: 3306, Schema: , Login: root, Password: ***, extra: {}
[2021-08-07 16:36:19,762] {dbapi.py:204} INFO - Running statement: CREATE TABLE IF NOT EXISTS presentation.DATE (
    `DATE_KEY` int NOT NULL AUTO_INCREMENT,
    `DAY` int NOT NULL,
    `WEEK` int NOT NULL,
    `MONTH` int NOT NULL,
    `QUARTER` int NOT NULL,
    `YEAR` int NOT NULL,
    `INGESTION_TIMESTAMP` datetime DEFAULT CURRENT_TIMESTAMP,
    CONSTRAINT `PK_CUSTOMER` PRIMARY KEY (`CUSTOMER_KEY`)
) ENGINE=InnoDB DEFAULT CHARSET=utf8mb4 COLLATE=utf8mb4_0900_ai_ci;, parameters: None
[2021-08-07 16:36:19,764] {taskinstance.py:1501} ERROR - Task failed with exception
Traceback (most recent call last):
  File "/home/airflow/.local/lib/python3.6/site-packages/airflow/models/taskinstance.py", line 1157, in _run_raw_task
    self._prepare_and_execute_task_with_callbacks(context, task)
  File "/home/airflow/.local/lib/python3.6/site-packages/airflow/models/taskinstance.py", line 1331, in _prepare_and_execute_task_with_callbacks
    result = self._execute_task(context, task_copy)
  File "/home/airflow/.local/lib/python3.6/site-packages/airflow/models/taskinstance.py", line 1361, in _execute_task
    result = task_copy.execute(context=context)
  File "/home/airflow/.local/lib/python3.6/site-packages/airflow/providers/mysql/operators/mysql.py", line 72, in execute
    hook.run(self.sql, autocommit=self.autocommit, parameters=self.parameters)
  File "/home/airflow/.local/lib/python3.6/site-packages/airflow/hooks/dbapi.py", line 184, in run
    self._run_command(cur, sql_statement, parameters)
  File "/home/airflow/.local/lib/python3.6/site-packages/airflow/hooks/dbapi.py", line 208, in _run_command
    cur.execute(sql_statement)
  File "/home/airflow/.local/lib/python3.6/site-packages/MySQLdb/cursors.py", line 206, in execute
    res = self._query(query)
  File "/home/airflow/.local/lib/python3.6/site-packages/MySQLdb/cursors.py", line 319, in _query
    db.query(q)
  File "/home/airflow/.local/lib/python3.6/site-packages/MySQLdb/connections.py", line 259, in query
    _mysql.connection.query(self, query)
MySQLdb._exceptions.OperationalError: (1072, "Key column 'CUSTOMER_KEY' doesn't exist in table")
[2021-08-07 16:36:19,769] {taskinstance.py:1551} INFO - Marking task as FAILED. dag_id=presentation_pipeline, task_id=create_presentation_table_date, execution_date=20210807T163000, start_date=20210807T163619, end_date=20210807T163619
[2021-08-07 16:36:19,831] {local_task_job.py:149} INFO - Task exited with return code 1
