[2021-08-08 02:02:26,917] {taskinstance.py:896} INFO - Dependencies all met for <TaskInstance: standardized_pipeline.create_standardized_table_customers 2021-08-08T01:55:00+00:00 [queued]>
[2021-08-08 02:02:27,013] {taskinstance.py:896} INFO - Dependencies all met for <TaskInstance: standardized_pipeline.create_standardized_table_customers 2021-08-08T01:55:00+00:00 [queued]>
[2021-08-08 02:02:27,018] {taskinstance.py:1087} INFO - 
--------------------------------------------------------------------------------
[2021-08-08 02:02:27,021] {taskinstance.py:1088} INFO - Starting attempt 1 of 1
[2021-08-08 02:02:27,023] {taskinstance.py:1089} INFO - 
--------------------------------------------------------------------------------
[2021-08-08 02:02:27,056] {taskinstance.py:1107} INFO - Executing <Task(MySqlOperator): create_standardized_table_customers> on 2021-08-08T01:55:00+00:00
[2021-08-08 02:02:27,082] {standard_task_runner.py:52} INFO - Started process 3538 to run task
[2021-08-08 02:02:27,155] {standard_task_runner.py:76} INFO - Running: ['***', 'tasks', 'run', 'standardized_pipeline', 'create_standardized_table_customers', '2021-08-08T01:55:00+00:00', '--job-id', '15', '--pool', 'default_pool', '--raw', '--subdir', 'DAGS_FOLDER/standardized_pipeline.py', '--cfg-path', '/tmp/tmp_n2ivszi', '--error-file', '/tmp/tmpe411rj0i']
[2021-08-08 02:02:27,160] {standard_task_runner.py:77} INFO - Job 15: Subtask create_standardized_table_customers
[2021-08-08 02:02:27,473] {logging_mixin.py:104} INFO - Running <TaskInstance: standardized_pipeline.create_standardized_table_customers 2021-08-08T01:55:00+00:00 [running]> on host 02070657999c
[2021-08-08 02:02:27,727] {taskinstance.py:1302} INFO - Exporting the following env vars:
AIRFLOW_CTX_DAG_OWNER=***
AIRFLOW_CTX_DAG_ID=standardized_pipeline
AIRFLOW_CTX_TASK_ID=create_standardized_table_customers
AIRFLOW_CTX_EXECUTION_DATE=2021-08-08T01:55:00+00:00
AIRFLOW_CTX_DAG_RUN_ID=scheduled__2021-08-08T01:55:00+00:00
[2021-08-08 02:02:27,738] {mysql.py:70} INFO - Executing: CREATE TABLE IF NOT EXISTS customers AS
WITH data_last_5_minutes AS (
	SELECT
		DISTINCT 
		CAST(C_CUSTKEY AS SIGNED) AS CUSTOMER_KEY,
		C_NAME AS CUSTOMER_NAME,
		C_ADDRESS AS CUSTOMER_ADDRESS,
		CAST(C_NATIONKEY AS SIGNED) AS NATION_KEY,
		C_PHONE AS CUSTOMER_PHONE,
		C_ACCTBAL AS CUSTOMER_ACCOUNT_BALANCE_TOTAL,
		C_MKTSEGMENT AS CUSTOMER_MARKET_SEGMENT_TYPE,
		C_COMMENT AS CUSTOMER_COMMENT
	FROM
		datalake.CUSTOMER
	WHERE 
		INGESTION_TIMESTAMP >= DATE_SUB(NOW(), INTERVAL 5 MINUTE)
)

SELECT 
	* 
FROM 
	data_last_5_minutes
[2021-08-08 02:02:27,808] {taskinstance.py:1501} ERROR - Task failed with exception
Traceback (most recent call last):
  File "/home/airflow/.local/lib/python3.6/site-packages/airflow/models/taskinstance.py", line 1157, in _run_raw_task
    self._prepare_and_execute_task_with_callbacks(context, task)
  File "/home/airflow/.local/lib/python3.6/site-packages/airflow/models/taskinstance.py", line 1331, in _prepare_and_execute_task_with_callbacks
    result = self._execute_task(context, task_copy)
  File "/home/airflow/.local/lib/python3.6/site-packages/airflow/models/taskinstance.py", line 1361, in _execute_task
    result = task_copy.execute(context=context)
  File "/home/airflow/.local/lib/python3.6/site-packages/airflow/providers/mysql/operators/mysql.py", line 72, in execute
    hook.run(self.sql, autocommit=self.autocommit, parameters=self.parameters)
  File "/home/airflow/.local/lib/python3.6/site-packages/airflow/hooks/dbapi.py", line 177, in run
    with closing(self.get_conn()) as conn:
  File "/home/airflow/.local/lib/python3.6/site-packages/airflow/providers/mysql/hooks/mysql.py", line 164, in get_conn
    getattr(self, self.conn_name_attr)
  File "/home/airflow/.local/lib/python3.6/site-packages/airflow/hooks/base.py", line 67, in get_connection
    conn = Connection.get_connection_from_secrets(conn_id)
  File "/home/airflow/.local/lib/python3.6/site-packages/airflow/models/connection.py", line 379, in get_connection_from_secrets
    raise AirflowNotFoundException(f"The conn_id `{conn_id}` isn't defined")
airflow.exceptions.AirflowNotFoundException: The conn_id `dwh_id` isn't defined
[2021-08-08 02:02:27,818] {taskinstance.py:1551} INFO - Marking task as FAILED. dag_id=standardized_pipeline, task_id=create_standardized_table_customers, execution_date=20210808T015500, start_date=20210808T020226, end_date=20210808T020227
[2021-08-08 02:02:27,909] {local_task_job.py:149} INFO - Task exited with return code 1
