[2021-08-08 07:12:13,114] {taskinstance.py:896} INFO - Dependencies all met for <TaskInstance: to_datalake_pipeline.extract_from_git 2021-08-08T06:10:00+00:00 [queued]>
[2021-08-08 07:12:13,130] {taskinstance.py:896} INFO - Dependencies all met for <TaskInstance: to_datalake_pipeline.extract_from_git 2021-08-08T06:10:00+00:00 [queued]>
[2021-08-08 07:12:13,131] {taskinstance.py:1087} INFO - 
--------------------------------------------------------------------------------
[2021-08-08 07:12:13,131] {taskinstance.py:1088} INFO - Starting attempt 3 of 11
[2021-08-08 07:12:13,132] {taskinstance.py:1089} INFO - 
--------------------------------------------------------------------------------
[2021-08-08 07:12:13,139] {taskinstance.py:1107} INFO - Executing <Task(PythonOperator): extract_from_git> on 2021-08-08T06:10:00+00:00
[2021-08-08 07:12:13,144] {standard_task_runner.py:52} INFO - Started process 884 to run task
[2021-08-08 07:12:13,148] {standard_task_runner.py:76} INFO - Running: ['***', 'tasks', 'run', 'to_datalake_pipeline', 'extract_from_git', '2021-08-08T06:10:00+00:00', '--job-id', '64', '--pool', 'default_pool', '--raw', '--subdir', 'DAGS_FOLDER/to_datalake_pipeline.py', '--cfg-path', '/tmp/tmpprqe_bh5', '--error-file', '/tmp/tmpwe3nzsf0']
[2021-08-08 07:12:13,149] {standard_task_runner.py:77} INFO - Job 64: Subtask extract_from_git
[2021-08-08 07:12:13,194] {logging_mixin.py:104} INFO - Running <TaskInstance: to_datalake_pipeline.extract_from_git 2021-08-08T06:10:00+00:00 [running]> on host bf836d82c89b
[2021-08-08 07:12:13,243] {taskinstance.py:1302} INFO - Exporting the following env vars:
AIRFLOW_CTX_DAG_EMAIL=wildangbudhi@gmail.com
AIRFLOW_CTX_DAG_OWNER=***
AIRFLOW_CTX_DAG_ID=to_datalake_pipeline
AIRFLOW_CTX_TASK_ID=extract_from_git
AIRFLOW_CTX_EXECUTION_DATE=2021-08-08T06:10:00+00:00
AIRFLOW_CTX_DAG_RUN_ID=scheduled__2021-08-08T06:10:00+00:00
[2021-08-08 07:12:13,244] {logging_mixin.py:104} INFO - Downloading data from -> https://raw.githubusercontent.com/rezaprimasatya/DTO-DE-JUN-MID/main/data.zip
[2021-08-08 07:12:24,791] {logging_mixin.py:104} INFO - Unzipping Data
[2021-08-08 07:12:24,861] {logging_mixin.py:104} INFO - Transform Data to Pandas Dataframe
[2021-08-08 07:12:25,062] {logging_mixin.py:104} INFO - Load data to datalake
[2021-08-08 07:12:25,097] {logging_mixin.py:104} INFO - Load table : REGION
[2021-08-08 07:12:25,117] {taskinstance.py:1501} ERROR - Task failed with exception
Traceback (most recent call last):
  File "/home/airflow/.local/lib/python3.6/site-packages/airflow/models/taskinstance.py", line 1157, in _run_raw_task
    self._prepare_and_execute_task_with_callbacks(context, task)
  File "/home/airflow/.local/lib/python3.6/site-packages/airflow/models/taskinstance.py", line 1331, in _prepare_and_execute_task_with_callbacks
    result = self._execute_task(context, task_copy)
  File "/home/airflow/.local/lib/python3.6/site-packages/airflow/models/taskinstance.py", line 1361, in _execute_task
    result = task_copy.execute(context=context)
  File "/home/airflow/.local/lib/python3.6/site-packages/airflow/operators/python.py", line 150, in execute
    return_value = self.execute_callable()
  File "/home/airflow/.local/lib/python3.6/site-packages/airflow/operators/python.py", line 161, in execute_callable
    return self.python_callable(*self.op_args, **self.op_kwargs)
  File "/opt/airflow/dags/extract/extract.py", line 104, in extract_data_from_git
    pipeline.run()
  File "/opt/airflow/dags/extract/extract.py", line 19, in run
    self.df_to_datalake(data_dataframes)
  File "/opt/airflow/dags/extract/extract.py", line 98, in df_to_datalake
    df.columns = columns
  File "/home/airflow/.local/lib/python3.6/site-packages/pandas/core/generic.py", line 5154, in __setattr__
    return object.__setattr__(self, name, value)
  File "pandas/_libs/properties.pyx", line 66, in pandas._libs.properties.AxisProperty.__set__
  File "/home/airflow/.local/lib/python3.6/site-packages/pandas/core/generic.py", line 564, in _set_axis
    self._mgr.set_axis(axis, labels)
  File "/home/airflow/.local/lib/python3.6/site-packages/pandas/core/internals/managers.py", line 227, in set_axis
    f"Length mismatch: Expected axis has {old_len} elements, new "
ValueError: Length mismatch: Expected axis has 3 elements, new values have 0 elements
[2021-08-08 07:12:25,121] {taskinstance.py:1551} INFO - Marking task as UP_FOR_RETRY. dag_id=to_datalake_pipeline, task_id=extract_from_git, execution_date=20210808T061000, start_date=20210808T071213, end_date=20210808T071225
[2021-08-08 07:12:25,193] {local_task_job.py:149} INFO - Task exited with return code 1
